[32m2024-06-15 20:49:59 +0545[0m - dagster - [34mDEBUG[0m - __ASSET_JOB - 6fb42434-11c1-43af-afbf-15768f821cca - 396269 - LOGS_CAPTURED - Started capturing logs in process (pid: 396269).
[32m2024-06-15 20:49:59 +0545[0m - dagster - [34mDEBUG[0m - __ASSET_JOB - 6fb42434-11c1-43af-afbf-15768f821cca - 396269 - taxi_zones_file - STEP_START - Started execution of step "taxi_zones_file".
[32m2024-06-15 20:50:00 +0545[0m - dagster - [34mERROR[0m - [31m__ASSET_JOB - 6fb42434-11c1-43af-afbf-15768f821cca - 396269 - taxi_zones_file - STEP_FAILURE - Execution of step "taxi_zones_file" failed.

dagster._core.errors.DagsterExecutionStepExecutionError: Error occurred while executing op "taxi_zones_file"::

TypeError: a bytes-like object is required, not 'Response'

Stack Trace:
  File "/home/mikeyy/projects/personal_projects/Looking-Into-Dagster/venv/lib/python3.10/site-packages/dagster/_core/execution/plan/utils.py", line 54, in op_execution_error_boundary
    yield
  File "/home/mikeyy/projects/personal_projects/Looking-Into-Dagster/venv/lib/python3.10/site-packages/dagster/_utils/__init__.py", line 468, in iterate_with_context
    next_output = next(iterator)
  File "/home/mikeyy/projects/personal_projects/Looking-Into-Dagster/venv/lib/python3.10/site-packages/dagster/_core/execution/plan/compute_generator.py", line 141, in _coerce_op_compute_fn_to_iterator
    result = invoke_compute_fn(
  File "/home/mikeyy/projects/personal_projects/Looking-Into-Dagster/venv/lib/python3.10/site-packages/dagster/_core/execution/plan/compute_generator.py", line 129, in invoke_compute_fn
    return fn(context, **args_to_pass) if context_arg_provided else fn(**args_to_pass)
  File "/home/mikeyy/projects/personal_projects/Looking-Into-Dagster/dagster_university/dagster_university/assets/trips.py", line 31, in taxi_zones_file
    f.write(data)
[0m
